Workbook

Sheet Summary
A1: World Cup 2026 — Bookmaker Prediction Accuracy
A2: Headline metrics (all live formulas off the Matches sheet)
A5: Matches completed | B5: =COUNTA(Matches!$C$5:$C$500) -> 72
A6: Correct predictions | B6: =SUM(Matches!$H$5:$H$500) -> 45
A7: Off | B7: =B5-B6 -> 27
A8: Overall accuracy | B8: =IF(B5=0,"",B6/B5) -> 0.625
A9: — of which: favorite held to draw | B9: =COUNTIF(Matches!$G$5:$G$500,"Draw") -> 20
A10: — of which: outright upsets | B10: =B7-B9 -> 7
A13: Method
A14: Prediction = the shortest-odds three-way outcome (the favorite to win; no draw was a shortest-odds outcome in this sample). Odds proxy: Fox Sports three-way moneylines, the consensus favorite across books; results cross-checked vs CBS/ESPN/Yahoo. Through 18 Jun 2026. Three 18 Jun favorites are ranking/home-inferred. Tournament still in progress — the title prediction is not yet gradable.
A21: How to update each matchday
A22: 1) On the Matches sheet, add one row per new match: Date, Round, teams, Predicted (favorite), line, Score, Actual winner (exact team name, or 'Draw'). The Correct column fills itself. 2) On By Matchday, add a row for the new date. All summary figures update on open / recalc.

Sheet Matches
A1: 2026 FIFA World Cup — Shortest-Odds Prediction vs. Actual Result
A2: A prediction is CORRECT when the shortest-odds (favorite) outcome actually occurs. Edit / add rows below; all totals recalculate automatically.
A4: Date | B4: Round | C4: Match (Fav vs Opp) | D4: Predicted (shortest-odds) | E4: Fav line / note | F4: Score | G4: Actual winner | H4: Correct | I4: Outcome type
A5: 46184 | B5: R1 | C5: Mexico v South Africa | D5: Mexico | E5: -241 | F5: 2-0 | G5: Mexico | H5: =IF($D5=$G5,1,0) -> 1 | I5: =IF($H5=1,"Correct",IF($G5="Draw","Draw (fav held)","Upset")) -> Correct
A6: 46184 | B6: R1 | C6: South Korea v Czechia | D6: South Korea | E6: +156 (slim) | F6: 2-1 | G6: South Korea | H6: =IF($D6=$G6,1,0) -> 1 | I6: =IF($H6=1,"Correct",IF($G6="Draw","Draw (fav held)","Upset")) -> Correct
A7: 46185 | B7: R1 | C7: Canada v Bosnia | D7: Canada | E7: fav held (draw +249) | F7: 1-1 | G7: Draw | H7: =IF($D7=$G7,1,0) -> 0 | I7: =IF($H7=1,"Correct",IF($G7="Draw","Draw (fav held)","Upset")) -> Draw (fav held)
A8: 46185 | B8: R1 | C8: USA v Paraguay | D8: USA | E8: +104 | F8: 4-1 | G8: USA | H8: =IF($D8=$G8,1,0) -> 1 | I8: =IF($H8=1,"Correct",IF($G8="Draw","Draw (fav held)","Upset")) -> Correct
A9: 46186 | B9: R1 | C9: Qatar v Switzerland | D9: Switzerland | E9: fav held (draw +600) | F9: 1-1 | G9: Draw | H9: =IF($D9=$G9,1,0) -> 0 | I9: =IF($H9=1,"Correct",IF($G9="Draw","Draw (fav held)","Upset")) -> Draw (fav held)
A10: 46186 | B10: R1 | C10: Brazil v Morocco | D10: Brazil | E10: fav held (draw +270) | F10: 1-1 | G10: Draw | H10: =IF($D10=$G10,1,0) -> 0 | I10: =IF($H10=1,"Correct",IF($G10="Draw","Draw (fav held)","Upset")) -> Draw (fav held)
A11: 46186 | B11: R1 | C11: Haiti v Scotland | D11: Scotland | E11: -173 | F11: 0-1 | G11: Scotland | H11: =IF($D11=$G11,1,0) -> 1 | I11: =IF($H11=1,"Correct",IF($G11="Draw","Draw (fav held)","Upset")) -> Correct
A12: 46186 | B12: R1 | C12: Australia v Turkiye | D12: Turkiye | E12: upset (AUS +434 won) | F12: 2-0 | G12: Australia | H12: =IF($D12=$G12,1,0) -> 0 | I12: =IF($H12=1,"Correct",IF($G12="Draw","Draw (fav held)","Upset")) -> Upset
A13: 46187 | B13: R1 | C13: Germany v Curacao | D13: Germany | E13: -2857 | F13: 7-1 | G13: Germany | H13: =IF($D13=$G13,1,0) -> 1 | I13: =IF($H13=1,"Correct",IF($G13="Draw","Draw (fav held)","Upset")) -> Correct
A14: 46187 | B14: R1 | C14: Netherlands v Japan | D14: Netherlands | E14: fav held (draw +243) | F14: 2-2 | G14: Draw | H14: =IF($D14=$G14,1,0) -> 0 | I14: =IF($H14=1,"Correct",IF($G14="Draw","Draw (fav held)","Upset")) -> Draw (fav held)
A15: 46187 | B15: R1 | C15: Ivory Coast v Ecuador | D15: Ecuador | E15: upset (CIV +228 won) | F15: 1-0 | G15: Ivory Coast | H15: =IF($D15=$G15,1,0) -> 0 | I15: =IF($H15=1,"Correct",IF($G15="Draw","Draw (fav held)","Upset")) -> Upset
A16: 46187 | B16: R1 | C16: Sweden v Tunisia | D16: Sweden | E16: -116 | F16: 5-1 | G16: Sweden | H16: =IF($D16=$G16,1,0) -> 1 | I16: =IF($H16=1,"Correct",IF($G16="Draw","Draw (fav held)","Upset")) -> Correct
... A76: 46200 | B76: R3 | C76: Jordan v Argentina | D76: Argentina | E76: clear | F76: 1-3 | G76: Argentina | H76: =IF($D76=$G76,1,0) -> 1 | I76: =IF($H76=1,"Correct",IF($G76="Draw","Draw (fav held)","Upset")) -> Correct

Sheet By Matchday
A1: Accuracy by Matchday (daily + cumulative)
A2: Live formulas reading the Matches sheet. Full group stage (11-27 Jun).
A4: Date | B4: Round | C4: Matches | D4: Correct | E4: Off | F4: Day accuracy | G4: Cum. correct | H4: Cum. matches | I4: Cumulative accuracy
A5: 46184 | B5: R1 | C5: =COUNTIFS(Matches!$A$5:$A$200,$A5) -> 2 | D5: =SUMIFS(Matches!$H$5:$H$200,Matches!$A$5:$A$200,$A5) -> 2 | E5: =C5-D5 -> 0 | F5: =IF(C5=0,"",D5/C5) -> 1 | G5: =SUMIFS(Matches!$H$5:$H$200,Matches!$A$5:$A$200,"<="&$A5) -> 2 | H5: =COUNTIFS(Matches!$A$5:$A$200,"<="&$A5) -> 2 | I5: =IF(H5=0,"",G5/H5) -> 1
A6: 46185 | B6: R1 | C6: =COUNTIFS(Matches!$A$5:$A$200,$A6) -> 2 | D6: =SUMIFS(Matches!$H$5:$H$200,Matches!$A$5:$A$200,$A6) -> 1 | E6: =C6-D6 -> 1 | F6: =IF(C6=0,"",D6/C6) -> 0.5 | G6: =SUMIFS(Matches!$H$5:$H$200,Matches!$A$5:$A$200,"<="&$A6) -> 3 | H6: =COUNTIFS(Matches!$A$5:$A$200,"<="&$A6) -> 4 | I6: =IF(H6=0,"",G6/H6) -> 0.75
A7: 46186 | B7: R1 | C7: =COUNTIFS(Matches!$A$5:$A$200,$A7) -> 4 | D7: =SUMIFS(Matches!$H$5:$H$200,Matches!$A$5:$A$200,$A7) -> 1 | E7: =C7-D7 -> 3 | F7: =IF(C7=0,"",D7/C7) -> 0.25 | G7: =SUMIFS(Matches!$H$5:$H$200,Matches!$A$5:$A$200,"<="&$A7) -> 4 | H7: =COUNTIFS(Matches!$A$5:$A$200,"<="&$A7) -> 8 | I7: =IF(H7=0,"",G7/H7) -> 0.5
A8: 46187 | B8: R1 | C8: =COUNTIFS(Matches!$A$5:$A$200,$A8) -> 4 | D8: =SUMIFS(Matches!$H$5:$H$200,Matches!$A$5:$A$200,$A8) -> 2 | E8: =C8-D8 -> 2 | F8: =IF(C8=0,"",D8/C8) -> 0.5 | G8: =SUMIFS(Matches!$H$5:$H$200,Matches!$A$5:$A$200,"<="&$A8) -> 6 | H8: =COUNTIFS(Matches!$A$5:$A$200,"<="&$A8) -> 12 | I8: =IF(H8=0,"",G8/H8) -> 0.5
A9: 46188 | B9: R1 | C9: =COUNTIFS(Matches!$A$5:$A$200,$A9) -> 4 | D9: =SUMIFS(Matches!$H$5:$H$200,Matches!$A$5:$A$200,$A9) -> 0 | E9: =C9-D9 -> 4 | F9: =IF(C9=0,"",D9/C9) -> 0 | G9: =SUMIFS(Matches!$H$5:$H$200,Matches!$A$5:$A$200,"<="&$A9) -> 6 | H9: =COUNTIFS(Matches!$A$5:$A$200,"<="&$A9) -> 16 | I9: =IF(H9=0,"",G9/H9) -> 0.375
A10: 46189 | B10: R1 | C10: =COUNTIFS(Matches!$A$5:$A$200,$A10) -> 4 | D10: =SUMIFS(Matches!$H$5:$H$200,Matches!$A$5:$A$200,$A10) -> 4 | E10: =C10-D10 -> 0 | F10: =IF(C10=0,"",D10/C10) -> 1 | G10: =SUMIFS(Matches!$H$5:$H$200,Matches!$A$5:$A$200,"<="&$A10) -> 10 | H10: =COUNTIFS(Matches!$A$5:$A$200,"<="&$A10) -> 20 | I10: =IF(H10=0,"",G10/H10) -> 0.5
A11: 46190 | B11: R1 | C11: =COUNTIFS(Matches!$A$5:$A$200,$A11) -> 4 | D11: =SUMIFS(Matches!$H$5:$H$200,Matches!$A$5:$A$200,$A11) -> 3 | E11: =C11-D11 -> 1 | F11: =IF(C11=0,"",D11/C11) -> 0.75 | G11: =SUMIFS(Matches!$H$5:$H$200,Matches!$A$5:$A$200,"<="&$A11) -> 13 | H11: =COUNTIFS(Matches!$A$5:$A$200,"<="&$A11) -> 24 | I11: =IF(H11=0,"",G11/H11) -> 0.54166667
A12: 46191 | B12: R2 | C12: =COUNTIFS(Matches!$A$5:$A$200,$A12) -> 4 | D12: =SUMIFS(Matches!$H$5:$H$200,Matches!$A$5:$A$200,$A12) -> 3 | E12: =C12-D12 -> 1 | F12: =IF(C12=0,"",D12/C12) -> 0.75 | G12: =SUMIFS(Matches!$H$5:$H$200,Matches!$A$5:$A$200,"<="&$A12) -> 16 | H12: =COUNTIFS(Matches!$A$5:$A$200,"<="&$A12) -> 28 | I12: =IF(H12=0,"",G12/H12) -> 0.57142857
A13: 46192 | B13: R2 | C13: =COUNTIFS(Matches!$A$5:$A$200,$A13) -> 4 | D13: =SUMIFS(Matches!$H$5:$H$200,Matches!$A$5:$A$200,$A13) -> 3 | E13: =C13-D13 -> 1 | F13: =IF(C13=0,"",D13/C13) -> 0.75 | G13: =SUMIFS(Matches!$H$5:$H$200,Matches!$A$5:$A$200,"<="&$A13) -> 19 | H13: =COUNTIFS(Matches!$A$5:$A$200,"<="&$A13) -> 32 | I13: =IF(H13=0,"",G13/H13) -> 0.59375
A14: 46193 | B14: R2 | C14: =COUNTIFS(Matches!$A$5:$A$200,$A14) -> 3 | D14: =SUMIFS(Matches!$H$5:$H$200,Matches!$A$5:$A$200,$A14) -> 2 | E14: =C14-D14 -> 1 | F14: =IF(C14=0,"",D14/C14) -> 0.66666667 | G14: =SUMIFS(Matches!$H$5:$H$200,Matches!$A$5:$A$200,"<="&$A14) -> 21 | H14: =COUNTIFS(Matches!$A$5:$A$200,"<="&$A14) -> 35 | I14: =IF(H14=0,"",G14/H14) -> 0.6
A15: 46194 | B15: R2 | C15: =COUNTIFS(Matches!$A$5:$A$200,$A15) -> 5 | D15: =SUMIFS(Matches!$H$5:$H$200,Matches!$A$5:$A$200,$A15) -> 3 | E15: =C15-D15 -> 2 | F15: =IF(C15=0,"",D15/C15) -> 0.6 | G15: =SUMIFS(Matches!$H$5:$H$200,Matches!$A$5:$A$200,"<="&$A15) -> 24 | H15: =COUNTIFS(Matches!$A$5:$A$200,"<="&$A15) -> 40 | I15: =IF(H15=0,"",G15/H15) -> 0.6
A16: 46195 | B16: R2 | C16: =COUNTIFS(Matches!$A$5:$A$200,$A16) -> 4 | D16: =SUMIFS(Matches!$H$5:$H$200,Matches!$A$5:$A$200,$A16) -> 4 | E16: =C16-D16 -> 0 | F16: =IF(C16=0,"",D16/C16) -> 1 | G16: =SUMIFS(Matches!$H$5:$H$200,Matches!$A$5:$A$200,"<="&$A16) -> 28 | H16: =COUNTIFS(Matches!$A$5:$A$200,"<="&$A16) -> 44 | I16: =IF(H16=0,"",G16/H16) -> 0.63636364
... A21: 46200 | B21: R3 | C21: =COUNTIFS(Matches!$A$5:$A$200,$A21) -> 6 | D21: =SUMIFS(Matches!$H$5:$H$200,Matches!$A$5:$A$200,$A21) -> 4 | E21: =C21-D21 -> 2 | F21: =IF(C21=0,"",D21/C21) -> 0.66666667 | G21: =SUMIFS(Matches!$H$5:$H$200,Matches!$A$5:$A$200,"<="&$A21) -> 45 | H21: =COUNTIFS(Matches!$A$5:$A$200,"<="&$A21) -> 72 | I21: =IF(H21=0,"",G21/H21) -> 0.625
A22: TOTAL | C22: =SUM(C5:C21) -> 72 | D22: =SUM(D5:D21) -> 45 | E22: =SUM(E5:E21) -> 27 | F22: =IF(C22=0,"",D22/C22) -> 0.625 | I22: =IF(C22=0,"",D22/C22) -> 0.625

Sheet Knockout R32
A1: Knockout Stage — Shortest-Odds Prediction Accuracy (Round of 32)
A2: Predicted = pre-match favorite (shortest odds / 'to advance' consensus). Three tests per tie: did the favorite QUALIFY (win the tie), win at FULL-TIME (inside 90 mins), and — for ties going past 90 — win in EXTRA TIME/shootout. Add R16/QF/SF/Final rows below (through row 40); metrics recalc automatically.
A4: Date | B4: Match (Fav vs Opp) | C4: Favorite (predicted) | D4: Score (90 min) | E4: Decided by | F4: Advanced | G4: Went to ET | H4: Qualify ✓ | I4: FT winner ✓ | J4: ET winner ✓
A5: 46201 | B5: Canada v South Africa | C5: Canada | D5: 1-0 | E5: FT | F5: Canada | G5: =IF($B5="","",IF($E5="FT","No","Yes")) -> No | H5: =IF($B5="","",IF($C5=$F5,1,0)) -> 1 | I5: =IF($B5="","",IF(AND($E5="FT",$C5=$F5),1,0)) -> 1 | J5: =IF($B5="","",IF($G5="Yes",IF($C5=$F5,1,0),""))
A6: 46202 | B6: Brazil v Japan | C6: Brazil | D6: 2-1 | E6: FT | F6: Brazil | G6: =IF($B6="","",IF($E6="FT","No","Yes")) -> No | H6: =IF($B6="","",IF($C6=$F6,1,0)) -> 1 | I6: =IF($B6="","",IF(AND($E6="FT",$C6=$F6),1,0)) -> 1 | J6: =IF($B6="","",IF($G6="Yes",IF($C6=$F6,1,0),""))
A7: 46202 | B7: Germany v Paraguay | C7: Germany | D7: 1-1 | E7: Penalties | F7: Paraguay | G7: =IF($B7="","",IF($E7="FT","No","Yes")) -> Yes | H7: =IF($B7="","",IF($C7=$F7,1,0)) -> 0 | I7: =IF($B7="","",IF(AND($E7="FT",$C7=$F7),1,0)) -> 0 | J7: =IF($B7="","",IF($G7="Yes",IF($C7=$F7,1,0),"")) -> 0
A8: 46202 | B8: Netherlands v Morocco | C8: Netherlands | D8: 1-1 | E8: Penalties | F8: Morocco | G8: =IF($B8="","",IF($E8="FT","No","Yes")) -> Yes | H8: =IF($B8="","",IF($C8=$F8,1,0)) -> 0 | I8: =IF($B8="","",IF(AND($E8="FT",$C8=$F8),1,0)) -> 0 | J8: =IF($B8="","",IF($G8="Yes",IF($C8=$F8,1,0),"")) -> 0
A9: 46203 | B9: Norway v Ivory Coast | C9: Norway | D9: 2-1 | E9: FT | F9: Norway | G9: =IF($B9="","",IF($E9="FT","No","Yes")) -> No | H9: =IF($B9="","",IF($C9=$F9,1,0)) -> 1 | I9: =IF($B9="","",IF(AND($E9="FT",$C9=$F9),1,0)) -> 1 | J9: =IF($B9="","",IF($G9="Yes",IF($C9=$F9,1,0),""))
A10: 46203 | B10: France v Sweden | C10: France | D10: 3-0 | E10: FT | F10: France | G10: =IF($B10="","",IF($E10="FT","No","Yes")) -> No | H10: =IF($B10="","",IF($C10=$F10,1,0)) -> 1 | I10: =IF($B10="","",IF(AND($E10="FT",$C10=$F10),1,0)) -> 1 | J10: =IF($B10="","",IF($G10="Yes",IF($C10=$F10,1,0),""))
A11: 46203 | B11: Mexico v Ecuador | C11: Mexico | D11: 2-0 | E11: FT | F11: Mexico | G11: =IF($B11="","",IF($E11="FT","No","Yes")) -> No | H11: =IF($B11="","",IF($C11=$F11,1,0)) -> 1 | I11: =IF($B11="","",IF(AND($E11="FT",$C11=$F11),1,0)) -> 1 | J11: =IF($B11="","",IF($G11="Yes",IF($C11=$F11,1,0),""))
A12: 46204 | B12: England v DR Congo | C12: England | D12: 2-1 | E12: FT | F12: England | G12: =IF($B12="","",IF($E12="FT","No","Yes")) -> No | H12: =IF($B12="","",IF($C12=$F12,1,0)) -> 1 | I12: =IF($B12="","",IF(AND($E12="FT",$C12=$F12),1,0)) -> 1 | J12: =IF($B12="","",IF($G12="Yes",IF($C12=$F12,1,0),""))
A13: 46204 | B13: Belgium v Senegal | C13: Belgium | D13: 2-2 | E13: ET goal | F13: Belgium | G13: =IF($B13="","",IF($E13="FT","No","Yes")) -> Yes | H13: =IF($B13="","",IF($C13=$F13,1,0)) -> 1 | I13: =IF($B13="","",IF(AND($E13="FT",$C13=$F13),1,0)) -> 0 | J13: =IF($B13="","",IF($G13="Yes",IF($C13=$F13,1,0),"")) -> 1
A14: 46204 | B14: USA v Bosnia & Herz. | C14: USA | D14: 2-0 | E14: FT | F14: USA | G14: =IF($B14="","",IF($E14="FT","No","Yes")) -> No | H14: =IF($B14="","",IF($C14=$F14,1,0)) -> 1 | I14: =IF($B14="","",IF(AND($E14="FT",$C14=$F14),1,0)) -> 1 | J14: =IF($B14="","",IF($G14="Yes",IF($C14=$F14,1,0),""))
A15: 46205 | B15: Spain v Austria | C15: Spain | D15: 3-0 | E15: FT | F15: Spain | G15: =IF($B15="","",IF($E15="FT","No","Yes")) -> No | H15: =IF($B15="","",IF($C15=$F15,1,0)) -> 1 | I15: =IF($B15="","",IF(AND($E15="FT",$C15=$F15),1,0)) -> 1 | J15: =IF($B15="","",IF($G15="Yes",IF($C15=$F15,1,0),""))
A16: 46205 | B16: Portugal v Croatia | C16: Portugal | D16: 2-1 | E16: FT | F16: Portugal | G16: =IF($B16="","",IF($E16="FT","No","Yes")) -> No | H16: =IF($B16="","",IF($C16=$F16,1,0)) -> 1 | I16: =IF($B16="","",IF(AND($E16="FT",$C16=$F16),1,0)) -> 1 | J16: =IF($B16="","",IF($G16="Yes",IF($C16=$F16,1,0),""))
... A20: 46207 | B20: Colombia v Ghana | C20: Colombia | D20: 1-0 | E20: FT | F20: Colombia | G20: =IF($B20="","",IF($E20="FT","No","Yes")) -> No | H20: =IF($B20="","",IF($C20=$F20,1,0)) -> 1 | I20: =IF($B20="","",IF(AND($E20="FT",$C20=$F20),1,0)) -> 1 | J20: =IF($B20="","",IF($G20="Yes",IF($C20=$F20,1,0),""))
G21: =IF($B21="","",IF($E21="FT","No","Yes")) | H21: =IF($B21="","",IF($C21=$F21,1,0)) | I21: =IF($B21="","",IF(AND($E21="FT",$C21=$F21),1,0)) | J21: =IF($B21="","",IF($G21="Yes",IF($C21=$F21,1,0),""))
G22: =IF($B22="","",IF($E22="FT","No","Yes")) | H22: =IF($B22="","",IF($C22=$F22,1,0)) | I22: =IF($B22="","",IF(AND($E22="FT",$C22=$F22),1,0)) | J22: =IF($B22="","",IF($G22="Yes",IF($C22=$F22,1,0),""))
G23: =IF($B23="","",IF($E23="FT","No","Yes")) | H23: =IF($B23="","",IF($C23=$F23,1,0)) | I23: =IF($B23="","",IF(AND($E23="FT",$C23=$F23),1,0)) | J23: =IF($B23="","",IF($G23="Yes",IF($C23=$F23,1,0),""))
G24: =IF($B24="","",IF($E24="FT","No","Yes")) | H24: =IF($B24="","",IF($C24=$F24,1,0)) | I24: =IF($B24="","",IF(AND($E24="FT",$C24=$F24),1,0)) | J24: =IF($B24="","",IF($G24="Yes",IF($C24=$F24,1,0),""))
G25: =IF($B25="","",IF($E25="FT","No","Yes")) | H25: =IF($B25="","",IF($C25=$F25,1,0)) | I25: =IF($B25="","",IF(AND($E25="FT",$C25=$F25),1,0)) | J25: =IF($B25="","",IF($G25="Yes",IF($C25=$F25,1,0),""))
G26: =IF($B26="","",IF($E26="FT","No","Yes")) | H26: =IF($B26="","",IF($C26=$F26,1,0)) | I26: =IF($B26="","",IF(AND($E26="FT",$C26=$F26),1,0)) | J26: =IF($B26="","",IF($G26="Yes",IF($C26=$F26,1,0),""))
G27: =IF($B27="","",IF($E27="FT","No","Yes")) | H27: =IF($B27="","",IF($C27=$F27,1,0)) | I27: =IF($B27="","",IF(AND($E27="FT",$C27=$F27),1,0)) | J27: =IF($B27="","",IF($G27="Yes",IF($C27=$F27,1,0),""))
G28: =IF($B28="","",IF($E28="FT","No","Yes")) | H28: =IF($B28="","",IF($C28=$F28,1,0)) | I28: =IF($B28="","",IF(AND($E28="FT",$C28=$F28),1,0)) | J28: =IF($B28="","",IF($G28="Yes",IF($C28=$F28,1,0),""))
G29: =IF($B29="","",IF($E29="FT","No","Yes")) | H29: =IF($B29="","",IF($C29=$F29,1,0)) | I29: =IF($B29="","",IF(AND($E29="FT",$C29=$F29),1,0)) | J29: =IF($B29="","",IF($G29="Yes",IF($C29=$F29,1,0),""))
G30: =IF($B30="","",IF($E30="FT","No","Yes")) | H30: =IF($B30="","",IF($C30=$F30,1,0)) | I30: =IF($B30="","",IF(AND($E30="FT",$C30=$F30),1,0)) | J30: =IF($B30="","",IF($G30="Yes",IF($C30=$F30,1,0),""))
G31: =IF($B31="","",IF($E31="FT","No","Yes")) | H31: =IF($B31="","",IF($C31=$F31,1,0)) | I31: =IF($B31="","",IF(AND($E31="FT",$C31=$F31),1,0)) | J31: =IF($B31="","",IF($G31="Yes",IF($C31=$F31,1,0),""))
G32: =IF($B32="","",IF($E32="FT","No","Yes")) | H32: =IF($B32="","",IF($C32=$F32,1,0)) | I32: =IF($B32="","",IF(AND($E32="FT",$C32=$F32),1,0)) | J32: =IF($B32="","",IF($G32="Yes",IF($C32=$F32,1,0),""))
... G40: =IF($B40="","",IF($E40="FT","No","Yes")) | H40: =IF($B40="","",IF($C40=$F40,1,0)) | I40: =IF($B40="","",IF(AND($E40="FT",$C40=$F40),1,0)) | J40: =IF($B40="","",IF($G40="Yes",IF($C40=$F40,1,0),""))
B44: KNOCKOUT METRICS (Round of 32)
B45: Metric | C45: Correct | D45: Out of | E45: Accuracy
B46: 1) Qualifying — favorite advanced (won the tie) | C46: =SUM($H$5:$H$40) -> 14 | D46: =COUNTA($B$5:$B$40) -> 16 | E46: =IF(D46=0,"",C46/D46) -> 0.875
B47: 2) Full-time winner — favorite won inside 90 min | C47: =SUM($I$5:$I$40) -> 11 | D47: =COUNTA($B$5:$B$40) -> 16 | E47: =IF(D47=0,"",C47/D47) -> 0.6875
B48: 3) Extra-time winner — favorite won ties that reached ET | C48: =SUM($J$5:$J$40) -> 3 | D48: =COUNTIF($G$5:$G$40,"Yes") -> 5 | E48: =IF(D48=0,"",C48/D48) -> 0.6
B50: Notes
B51: • Qualifying upsets (favorite eliminated): Paraguay def. Germany (pens); Morocco def. Netherlands (pens).
B52: • Full-time metric counts only wins inside 90 min; the 5 ties reaching extra time all count as 'not won at FT'.
B53: • Of the 5 ET ties: Belgium & Argentina won via an ET goal; Egypt won on penalties; Germany & Netherlands lost on penalties.
B54: • Favorites set by odds / 'to advance' consensus (FanDuel, BetMGM, Fox). Group-stage tabs now cover the full group stage (11-27 Jun); close ties verified vs pre-match odds.

Sheet Odds & Scoring
A1: Odds & Scoring — devigged market probabilities and probabilistic accuracy
A2: Enter full 1X2 DECIMAL odds (Home/Draw/Away) from a SINGLE source per match (ideally the closing line). Each match is devigged independently (proportional normalisation). Metrics then populate automatically. Only 5 rows below carry genuine single-source 3-way prices; the rest are blank pending a real closing-odds feed.
A4: SCORING SUMMARY (live; over rows with odds entered)
A5: Matches with full 1X2 entered | B5: =COUNT($E$22:$E$140) -> 5
A6: Market mean RPS (lower=better) | B6: =IFERROR(AVERAGE($M$22:$M$140),"") -> 0.1681674
A7: Market mean Brier (0-2) | B7: =IFERROR(AVERAGE($N$22:$N$140),"") -> 0.40014993
A8: Market mean log-loss | B8: =IFERROR(AVERAGE($O$22:$O$140),"") -> 0.73060027
A9: Favourite-pick mean RPS | B9: =IFERROR(AVERAGE($Q$22:$Q$140),"") -> 0.2
A10: Uniform (1/3) mean RPS (ref) | B10: =IFERROR(AVERAGE($S$22:$S$140),"") -> 0.27777778
A11: RPS skill score: fav-pick vs market | B11: =IFERROR(1-AVERAGE($Q$22:$Q$140)/AVERAGE($M$22:$M$140),"") -> -0.18929114
A12: RPS skill score: market vs uniform | B12: =IFERROR(1-AVERAGE($M$22:$M$140)/AVERAGE($S$22:$S$140),"") -> 0.39459736
A13: Back-favourite ROI (flat 1u, at own price) | B13: =IFERROR(AVERAGE($R$22:$R$140),"") -> 0.372
A14: Mean CLV (needs entry odds in col T) | B14: =IFERROR(AVERAGE($U$22:$U$140),"")
A21: Date | B21: Match (Home v Away) | C21: 90' score | D21: Actual | E21: Home | F21: Draw | G21: Away | H21: Source | I21: Overround | J21: P(H) | K21: P(D) | L21: P(A) | M21: Mkt RPS | N21: Mkt Brier | O21: Mkt LogL | P21: Fav pick | Q21: Fav RPS | R21: Back-fav P/L | S21: Unif RPS | T21: Entry odds | U21: CLV %
A22: 46184 | B22: Mexico v South Africa | C22: 2-0 | D22: =IF($C22="","",IF(VALUE(LEFT($C22,FIND("-",$C22)-1))>VALUE(MID($C22,FIND("-",$C22)+1,5)),"H",IF(VALUE(LEFT($C22,FIND("-",$C22)-1))=VALUE(MID($C22,FIND("-",$C22)+1,5)),"D","A"))) -> H | I22: =IF($E22="","",1/$E22+1/$F22+1/$G22) | J22: =IF($E22="","",(1/$E22)/$I22) | K22: =IF($E22="","",(1/$F22)/$I22) | L22: =IF($E22="","",(1/$G22)/$I22) | M22: =IF($E22="","",0.5*(($J22-($D22="H")*1)^2+(($J22+$K22)-(($D22="H")*1+($D22="D")*1))^2)) | N22: =IF($E22="","",($J22-($D22="H")*1)^2+($K22-($D22="D")*1)^2+($L22-($D22="A")*1)^2) | O22: =IF($E22="","",-LN(IF($D22="H",$J22,IF($D22="D",$K22,$L22)))) | P22: =IF($E22="","",IF(AND($E22<=$F22,$E22<=$G22),"H",IF(AND($F22<=$E22,$F22<=$G22),"D","A"))) | Q22: =IF($E22="","",0.5*((($P22="H")*1-($D22="H")*1)^2+((($P22="H")*1+($P22="D")*1)-(($D22="H")*1+($D22="D")*1))^2)) | R22: =IF($E22="","",IF($P22=$D22,IF($P22="H",$E22,IF($P22="D",$F22,$G22))-1,-1)) | S22: =IF($E22="","",0.5*((1/3-($D22="H")*1)^2+((2/3)-(($D22="H")*1+($D22="D")*1))^2)) | U22: =IF(OR($T22="",$E22=""),"",$T22/IF($P22="H",$E22,IF($P22="D",$F22,$G22))-1)
A23: 46184 | B23: South Korea v Czechia | C23: 2-1 | D23: =IF($C23="","",IF(VALUE(LEFT($C23,FIND("-",$C23)-1))>VALUE(MID($C23,FIND("-",$C23)+1,5)),"H",IF(VALUE(LEFT($C23,FIND("-",$C23)-1))=VALUE(MID($C23,FIND("-",$C23)+1,5)),"D","A"))) -> H | I23: =IF($E23="","",1/$E23+1/$F23+1/$G23) | J23: =IF($E23="","",(1/$E23)/$I23) | K23: =IF($E23="","",(1/$F23)/$I23) | L23: =IF($E23="","",(1/$G23)/$I23) | M23: =IF($E23="","",0.5*(($J23-($D23="H")*1)^2+(($J23+$K23)-(($D23="H")*1+($D23="D")*1))^2)) | N23: =IF($E23="","",($J23-($D23="H")*1)^2+($K23-($D23="D")*1)^2+($L23-($D23="A")*1)^2) | O23: =IF($E23="","",-LN(IF($D23="H",$J23,IF($D23="D",$K23,$L23)))) | P23: =IF($E23="","",IF(AND($E23<=$F23,$E23<=$G23),"H",IF(AND($F23<=$E23,$F23<=$G23),"D","A"))) | Q23: =IF($E23="","",0.5*((($P23="H")*1-($D23="H")*1)^2+((($P23="H")*1+($P23="D")*1)-(($D23="H")*1+($D23="D")*1))^2)) | R23: =IF($E23="","",IF($P23=$D23,IF($P23="H",$E23,IF($P23="D",$F23,$G23))-1,-1)) | S23: =IF($E23="","",0.5*((1/3-($D23="H")*1)^2+((2/3)-(($D23="H")*1+($D23="D")*1))^2)) | U23: =IF(OR($T23="",$E23=""),"",$T23/IF($P23="H",$E23,IF($P23="D",$F23,$G23))-1)
A24: 46185 | B24: Canada v Bosnia | C24: 1-1 | D24: =IF($C24="","",IF(VALUE(LEFT($C24,FIND("-",$C24)-1))>VALUE(MID($C24,FIND("-",$C24)+1,5)),"H",IF(VALUE(LEFT($C24,FIND("-",$C24)-1))=VALUE(MID($C24,FIND("-",$C24)+1,5)),"D","A"))) -> D | I24: =IF($E24="","",1/$E24+1/$F24+1/$G24) | J24: =IF($E24="","",(1/$E24)/$I24) | K24: =IF($E24="","",(1/$F24)/$I24) | L24: =IF($E24="","",(1/$G24)/$I24) | M24: =IF($E24="","",0.5*(($J24-($D24="H")*1)^2+(($J24+$K24)-(($D24="H")*1+($D24="D")*1))^2)) | N24: =IF($E24="","",($J24-($D24="H")*1)^2+($K24-($D24="D")*1)^2+($L24-($D24="A")*1)^2) | O24: =IF($E24="","",-LN(IF($D24="H",$J24,IF($D24="D",$K24,$L24)))) | P24: =IF($E24="","",IF(AND($E24<=$F24,$E24<=$G24),"H",IF(AND($F24<=$E24,$F24<=$G24),"D","A"))) | Q24: =IF($E24="","",0.5*((($P24="H")*1-($D24="H")*1)^2+((($P24="H")*1+($P24="D")*1)-(($D24="H")*1+($D24="D")*1))^2)) | R24: =IF($E24="","",IF($P24=$D24,IF($P24="H",$E24,IF($P24="D",$F24,$G24))-1,-1)) | S24: =IF($E24="","",0.5*((1/3-($D24="H")*1)^2+((2/3)-(($D24="H")*1+($D24="D")*1))^2)) | U24: =IF(OR($T24="",$E24=""),"",$T24/IF($P24="H",$E24,IF($P24="D",$F24,$G24))-1)
A25: 46185 | B25: USA v Paraguay | C25: 4-1 | D25: =IF($C25="","",IF(VALUE(LEFT($C25,FIND("-",$C25)-1))>VALUE(MID($C25,FIND("-",$C25)+1,5)),"H",IF(VALUE(LEFT($C25,FIND("-",$C25)-1))=VALUE(MID($C25,FIND("-",$C25)+1,5)),"D","A"))) -> H | I25: =IF($E25="","",1/$E25+1/$F25+1/$G25) | J25: =IF($E25="","",(1/$E25)/$I25) | K25: =IF($E25="","",(1/$F25)/$I25) | L25: =IF($E25="","",(1/$G25)/$I25) | M25: =IF($E25="","",0.5*(($J25-($D25="H")*1)^2+(($J25+$K25)-(($D25="H")*1+($D25="D")*1))^2)) | N25: =IF($E25="","",($J25-($D25="H")*1)^2+($K25-($D25="D")*1)^2+($L25-($D25="A")*1)^2) | O25: =IF($E25="","",-LN(IF($D25="H",$J25,IF($D25="D",$K25,$L25)))) | P25: =IF($E25="","",IF(AND($E25<=$F25,$E25<=$G25),"H",IF(AND($F25<=$E25,$F25<=$G25),"D","A"))) | Q25: =IF($E25="","",0.5*((($P25="H")*1-($D25="H")*1)^2+((($P25="H")*1+($P25="D")*1)-(($D25="H")*1+($D25="D")*1))^2)) | R25: =IF($E25="","",IF($P25=$D25,IF($P25="H",$E25,IF($P25="D",$F25,$G25))-1,-1)) | S25: =IF($E25="","",0.5*((1/3-($D25="H")*1)^2+((2/3)-(($D25="H")*1+($D25="D")*1))^2)) | U25: =IF(OR($T25="",$E25=""),"",$T25/IF($P25="H",$E25,IF($P25="D",$F25,$G25))-1)
A26: 46186 | B26: Qatar v Switzerland | C26: 1-1 | D26: =IF($C26="","",IF(VALUE(LEFT($C26,FIND("-",$C26)-1))>VALUE(MID($C26,FIND("-",$C26)+1,5)),"H",IF(VALUE(LEFT($C26,FIND("-",$C26)-1))=VALUE(MID($C26,FIND("-",$C26)+1,5)),"D","A"))) -> D | I26: =IF($E26="","",1/$E26+1/$F26+1/$G26) | J26: =IF($E26="","",(1/$E26)/$I26) | K26: =IF($E26="","",(1/$F26)/$I26) | L26: =IF($E26="","",(1/$G26)/$I26) | M26: =IF($E26="","",0.5*(($J26-($D26="H")*1)^2+(($J26+$K26)-(($D26="H")*1+($D26="D")*1))^2)) | N26: =IF($E26="","",($J26-($D26="H")*1)^2+($K26-($D26="D")*1)^2+($L26-($D26="A")*1)^2) | O26: =IF($E26="","",-LN(IF($D26="H",$J26,IF($D26="D",$K26,$L26)))) | P26: =IF($E26="","",IF(AND($E26<=$F26,$E26<=$G26),"H",IF(AND($F26<=$E26,$F26<=$G26),"D","A"))) | Q26: =IF($E26="","",0.5*((($P26="H")*1-($D26="H")*1)^2+((($P26="H")*1+($P26="D")*1)-(($D26="H")*1+($D26="D")*1))^2)) | R26: =IF($E26="","",IF($P26=$D26,IF($P26="H",$E26,IF($P26="D",$F26,$G26))-1,-1)) | S26: =IF($E26="","",0.5*((1/3-($D26="H")*1)^2+((2/3)-(($D26="H")*1+($D26="D")*1))^2)) | U26: =IF(OR($T26="",$E26=""),"",$T26/IF($P26="H",$E26,IF($P26="D",$F26,$G26))-1)
A27: 46186 | B27: Brazil v Morocco | C27: 1-1 | D27: =IF($C27="","",IF(VALUE(LEFT($C27,FIND("-",$C27)-1))>VALUE(MID($C27,FIND("-",$C27)+1,5)),"H",IF(VALUE(LEFT($C27,FIND("-",$C27)-1))=VALUE(MID($C27,FIND("-",$C27)+1,5)),"D","A"))) -> D | I27: =IF($E27="","",1/$E27+1/$F27+1/$G27) | J27: =IF($E27="","",(1/$E27)/$I27) | K27: =IF($E27="","",(1/$F27)/$I27) | L27: =IF($E27="","",(1/$G27)/$I27) | M27: =IF($E27="","",0.5*(($J27-($D27="H")*1)^2+(($J27+$K27)-(($D27="H")*1+($D27="D")*1))^2)) | N27: =IF($E27="","",($J27-($D27="H")*1)^2+($K27-($D27="D")*1)^2+($L27-($D27="A")*1)^2) | O27: =IF($E27="","",-LN(IF($D27="H",$J27,IF($D27="D",$K27,$L27)))) | P27: =IF($E27="","",IF(AND($E27<=$F27,$E27<=$G27),"H",IF(AND($F27<=$E27,$F27<=$G27),"D","A"))) | Q27: =IF($E27="","",0.5*((($P27="H")*1-($D27="H")*1)^2+((($P27="H")*1+($P27="D")*1)-(($D27="H")*1+($D27="D")*1))^2)) | R27: =IF($E27="","",IF($P27=$D27,IF($P27="H",$E27,IF($P27="D",$F27,$G27))-1,-1)) | S27: =IF($E27="","",0.5*((1/3-($D27="H")*1)^2+((2/3)-(($D27="H")*1+($D27="D")*1))^2)) | U27: =IF(OR($T27="",$E27=""),"",$T27/IF($P27="H",$E27,IF($P27="D",$F27,$G27))-1)
A28: 46186 | B28: Haiti v Scotland | C28: 0-1 | D28: =IF($C28="","",IF(VALUE(LEFT($C28,FIND("-",$C28)-1))>VALUE(MID($C28,FIND("-",$C28)+1,5)),"H",IF(VALUE(LEFT($C28,FIND("-",$C28)-1))=VALUE(MID($C28,FIND("-",$C28)+1,5)),"D","A"))) -> A | I28: =IF($E28="","",1/$E28+1/$F28+1/$G28) | J28: =IF($E28="","",(1/$E28)/$I28) | K28: =IF($E28="","",(1/$F28)/$I28) | L28: =IF($E28="","",(1/$G28)/$I28) | M28: =IF($E28="","",0.5*(($J28-($D28="H")*1)^2+(($J28+$K28)-(($D28="H")*1+($D28="D")*1))^2)) | N28: =IF($E28="","",($J28-($D28="H")*1)^2+($K28-($D28="D")*1)^2+($L28-($D28="A")*1)^2) | O28: =IF($E28="","",-LN(IF($D28="H",$J28,IF($D28="D",$K28,$L28)))) | P28: =IF($E28="","",IF(AND($E28<=$F28,$E28<=$G28),"H",IF(AND($F28<=$E28,$F28<=$G28),"D","A"))) | Q28: =IF($E28="","",0.5*((($P28="H")*1-($D28="H")*1)^2+((($P28="H")*1+($P28="D")*1)-(($D28="H")*1+($D28="D")*1))^2)) | R28: =IF($E28="","",IF($P28=$D28,IF($P28="H",$E28,IF($P28="D",$F28,$G28))-1,-1)) | S28: =IF($E28="","",0.5*((1/3-($D28="H")*1)^2+((2/3)-(($D28="H")*1+($D28="D")*1))^2)) | U28: =IF(OR($T28="",$E28=""),"",$T28/IF($P28="H",$E28,IF($P28="D",$F28,$G28))-1)
A29: 46186 | B29: Australia v Turkiye | C29: 2-0 | D29: =IF($C29="","",IF(VALUE(LEFT($C29,FIND("-",$C29)-1))>VALUE(MID($C29,FIND("-",$C29)+1,5)),"H",IF(VALUE(LEFT($C29,FIND("-",$C29)-1))=VALUE(MID($C29,FIND("-",$C29)+1,5)),"D","A"))) -> H | I29: =IF($E29="","",1/$E29+1/$F29+1/$G29) | J29: =IF($E29="","",(1/$E29)/$I29) | K29: =IF($E29="","",(1/$F29)/$I29) | L29: =IF($E29="","",(1/$G29)/$I29) | M29: =IF($E29="","",0.5*(($J29-($D29="H")*1)^2+(($J29+$K29)-(($D29="H")*1+($D29="D")*1))^2)) | N29: =IF($E29="","",($J29-($D29="H")*1)^2+($K29-($D29="D")*1)^2+($L29-($D29="A")*1)^2) | O29: =IF($E29="","",-LN(IF($D29="H",$J29,IF($D29="D",$K29,$L29)))) | P29: =IF($E29="","",IF(AND($E29<=$F29,$E29<=$G29),"H",IF(AND($F29<=$E29,$F29<=$G29),"D","A"))) | Q29: =IF($E29="","",0.5*((($P29="H")*1-($D29="H")*1)^2+((($P29="H")*1+($P29="D")*1)-(($D29="H")*1+($D29="D")*1))^2)) | R29: =IF($E29="","",IF($P29=$D29,IF($P29="H",$E29,IF($P29="D",$F29,$G29))-1,-1)) | S29: =IF($E29="","",0.5*((1/3-($D29="H")*1)^2+((2/3)-(($D29="H")*1+($D29="D")*1))^2)) | U29: =IF(OR($T29="",$E29=""),"",$T29/IF($P29="H",$E29,IF($P29="D",$F29,$G29))-1)
A30: 46187 | B30: Germany v Curacao | C30: 7-1 | D30: =IF($C30="","",IF(VALUE(LEFT($C30,FIND("-",$C30)-1))>VALUE(MID($C30,FIND("-",$C30)+1,5)),"H",IF(VALUE(LEFT($C30,FIND("-",$C30)-1))=VALUE(MID($C30,FIND("-",$C30)+1,5)),"D","A"))) -> H | I30: =IF($E30="","",1/$E30+1/$F30+1/$G30) | J30: =IF($E30="","",(1/$E30)/$I30) | K30: =IF($E30="","",(1/$F30)/$I30) | L30: =IF($E30="","",(1/$G30)/$I30) | M30: =IF($E30="","",0.5*(($J30-($D30="H")*1)^2+(($J30+$K30)-(($D30="H")*1+($D30="D")*1))^2)) | N30: =IF($E30="","",($J30-($D30="H")*1)^2+($K30-($D30="D")*1)^2+($L30-($D30="A")*1)^2) | O30: =IF($E30="","",-LN(IF($D30="H",$J30,IF($D30="D",$K30,$L30)))) | P30: =IF($E30="","",IF(AND($E30<=$F30,$E30<=$G30),"H",IF(AND($F30<=$E30,$F30<=$G30),"D","A"))) | Q30: =IF($E30="","",0.5*((($P30="H")*1-($D30="H")*1)^2+((($P30="H")*1+($P30="D")*1)-(($D30="H")*1+($D30="D")*1))^2)) | R30: =IF($E30="","",IF($P30=$D30,IF($P30="H",$E30,IF($P30="D",$F30,$G30))-1,-1)) | S30: =IF($E30="","",0.5*((1/3-($D30="H")*1)^2+((2/3)-(($D30="H")*1+($D30="D")*1))^2)) | U30: =IF(OR($T30="",$E30=""),"",$T30/IF($P30="H",$E30,IF($P30="D",$F30,$G30))-1)
A31: 46187 | B31: Netherlands v Japan | C31: 2-2 | D31: =IF($C31="","",IF(VALUE(LEFT($C31,FIND("-",$C31)-1))>VALUE(MID($C31,FIND("-",$C31)+1,5)),"H",IF(VALUE(LEFT($C31,FIND("-",$C31)-1))=VALUE(MID($C31,FIND("-",$C31)+1,5)),"D","A"))) -> D | I31: =IF($E31="","",1/$E31+1/$F31+1/$G31) | J31: =IF($E31="","",(1/$E31)/$I31) | K31: =IF($E31="","",(1/$F31)/$I31) | L31: =IF($E31="","",(1/$G31)/$I31) | M31: =IF($E31="","",0.5*(($J31-($D31="H")*1)^2+(($J31+$K31)-(($D31="H")*1+($D31="D")*1))^2)) | N31: =IF($E31="","",($J31-($D31="H")*1)^2+($K31-($D31="D")*1)^2+($L31-($D31="A")*1)^2) | O31: =IF($E31="","",-LN(IF($D31="H",$J31,IF($D31="D",$K31,$L31)))) | P31: =IF($E31="","",IF(AND($E31<=$F31,$E31<=$G31),"H",IF(AND($F31<=$E31,$F31<=$G31),"D","A"))) | Q31: =IF($E31="","",0.5*((($P31="H")*1-($D31="H")*1)^2+((($P31="H")*1+($P31="D")*1)-(($D31="H")*1+($D31="D")*1))^2)) | R31: =IF($E31="","",IF($P31=$D31,IF($P31="H",$E31,IF($P31="D",$F31,$G31))-1,-1)) | S31: =IF($E31="","",0.5*((1/3-($D31="H")*1)^2+((2/3)-(($D31="H")*1+($D31="D")*1))^2)) | U31: =IF(OR($T31="",$E31=""),"",$T31/IF($P31="H",$E31,IF($P31="D",$F31,$G31))-1)
A32: 46187 | B32: Ivory Coast v Ecuador | C32: 1-0 | D32: =IF($C32="","",IF(VALUE(LEFT($C32,FIND("-",$C32)-1))>VALUE(MID($C32,FIND("-",$C32)+1,5)),"H",IF(VALUE(LEFT($C32,FIND("-",$C32)-1))=VALUE(MID($C32,FIND("-",$C32)+1,5)),"D","A"))) -> H | I32: =IF($E32="","",1/$E32+1/$F32+1/$G32) | J32: =IF($E32="","",(1/$E32)/$I32) | K32: =IF($E32="","",(1/$F32)/$I32) | L32: =IF($E32="","",(1/$G32)/$I32) | M32: =IF($E32="","",0.5*(($J32-($D32="H")*1)^2+(($J32+$K32)-(($D32="H")*1+($D32="D")*1))^2)) | N32: =IF($E32="","",($J32-($D32="H")*1)^2+($K32-($D32="D")*1)^2+($L32-($D32="A")*1)^2) | O32: =IF($E32="","",-LN(IF($D32="H",$J32,IF($D32="D",$K32,$L32)))) | P32: =IF($E32="","",IF(AND($E32<=$F32,$E32<=$G32),"H",IF(AND($F32<=$E32,$F32<=$G32),"D","A"))) | Q32: =IF($E32="","",0.5*((($P32="H")*1-($D32="H")*1)^2+((($P32="H")*1+($P32="D")*1)-(($D32="H")*1+($D32="D")*1))^2)) | R32: =IF($E32="","",IF($P32=$D32,IF($P32="H",$E32,IF($P32="D",$F32,$G32))-1,-1)) | S32: =IF($E32="","",0.5*((1/3-($D32="H")*1)^2+((2/3)-(($D32="H")*1+($D32="D")*1))^2)) | U32: =IF(OR($T32="",$E32=""),"",$T32/IF($P32="H",$E32,IF($P32="D",$F32,$G32))-1)
A33: 46187 | B33: Sweden v Tunisia | C33: 5-1 | D33: =IF($C33="","",IF(VALUE(LEFT($C33,FIND("-",$C33)-1))>VALUE(MID($C33,FIND("-",$C33)+1,5)),"H",IF(VALUE(LEFT($C33,FIND("-",$C33)-1))=VALUE(MID($C33,FIND("-",$C33)+1,5)),"D","A"))) -> H | I33: =IF($E33="","",1/$E33+1/$F33+1/$G33) | J33: =IF($E33="","",(1/$E33)/$I33) | K33: =IF($E33="","",(1/$F33)/$I33) | L33: =IF($E33="","",(1/$G33)/$I33) | M33: =IF($E33="","",0.5*(($J33-($D33="H")*1)^2+(($J33+$K33)-(($D33="H")*1+($D33="D")*1))^2)) | N33: =IF($E33="","",($J33-($D33="H")*1)^2+($K33-($D33="D")*1)^2+($L33-($D33="A")*1)^2) | O33: =IF($E33="","",-LN(IF($D33="H",$J33,IF($D33="D",$K33,$L33)))) | P33: =IF($E33="","",IF(AND($E33<=$F33,$E33<=$G33),"H",IF(AND($F33<=$E33,$F33<=$G33),"D","A"))) | Q33: =IF($E33="","",0.5*((($P33="H")*1-($D33="H")*1)^2+((($P33="H")*1+($P33="D")*1)-(($D33="H")*1+($D33="D")*1))^2)) | R33: =IF($E33="","",IF($P33=$D33,IF($P33="H",$E33,IF($P33="D",$F33,$G33))-1,-1)) | S33: =IF($E33="","",0.5*((1/3-($D33="H")*1)^2+((2/3)-(($D33="H")*1+($D33="D")*1))^2)) | U33: =IF(OR($T33="",$E33=""),"",$T33/IF($P33="H",$E33,IF($P33="D",$F33,$G33))-1)
... A52: 46192 | B52: Brazil v Haiti | C52: 3-0 | D52: =IF($C52="","",IF(VALUE(LEFT($C52,FIND("-",$C52)-1))>VALUE(MID($C52,FIND("-",$C52)+1,5)),"H",IF(VALUE(LEFT($C52,FIND("-",$C52)-1))=VALUE(MID($C52,FIND("-",$C52)+1,5)),"D","A"))) -> H | I52: =IF($E52="","",1/$E52+1/$F52+1/$G52) | J52: =IF($E52="","",(1/$E52)/$I52) | K52: =IF($E52="","",(1/$F52)/$I52) | L52: =IF($E52="","",(1/$G52)/$I52) | M52: =IF($E52="","",0.5*(($J52-($D52="H")*1)^2+(($J52+$K52)-(($D52="H")*1+($D52="D")*1))^2)) | N52: =IF($E52="","",($J52-($D52="H")*1)^2+($K52-($D52="D")*1)^2+($L52-($D52="A")*1)^2) | O52: =IF($E52="","",-LN(IF($D52="H",$J52,IF($D52="D",$K52,$L52)))) | P52: =IF($E52="","",IF(AND($E52<=$F52,$E52<=$G52),"H",IF(AND($F52<=$E52,$F52<=$G52),"D","A"))) | Q52: =IF($E52="","",0.5*((($P52="H")*1-($D52="H")*1)^2+((($P52="H")*1+($P52="D")*1)-(($D52="H")*1+($D52="D")*1))^2)) | R52: =IF($E52="","",IF($P52=$D52,IF($P52="H",$E52,IF($P52="D",$F52,$G52))-1,-1)) | S52: =IF($E52="","",0.5*((1/3-($D52="H")*1)^2+((2/3)-(($D52="H")*1+($D52="D")*1))^2)) | U52: =IF(OR($T52="",$E52=""),"",$T52/IF($P52="H",$E52,IF($P52="D",$F52,$G52))-1)
A53: 46192 | B53: Turkiye v Paraguay | C53: 0-1 | D53: =IF($C53="","",IF(VALUE(LEFT($C53,FIND("-",$C53)-1))>VALUE(MID($C53,FIND("-",$C53)+1,5)),"H",IF(VALUE(LEFT($C53,FIND("-",$C53)-1))=VALUE(MID($C53,FIND("-",$C53)+1,5)),"D","A"))) -> A | E53: 2.05 | F53: 3.35 | G53: 3.85 | H53: best-avail (illustrative) | I53: =IF($E53="","",1/$E53+1/$F53+1/$G53) -> 1.0460526 | J53: =IF($E53="","",(1/$E53)/$I53) -> 0.46632921 | K53: =IF($E53="","",(1/$F53)/$I53) -> 0.28536563 | L53: =IF($E53="","",(1/$G53)/$I53) -> 0.24830516 | M53: =IF($E53="","",0.5*(($J53-($D53="H")*1)^2+(($J53+$K53)-(($D53="H")*1+($D53="D")*1))^2)) -> 0.39125403 | N53: =IF($E53="","",($J53-($D53="H")*1)^2+($K53-($D53="D")*1)^2+($L53-($D53="A")*1)^2) -> 0.8639416 | O53: =IF($E53="","",-LN(IF($D53="H",$J53,IF($D53="D",$K53,$L53)))) -> 1.3930968 | P53: =IF($E53="","",IF(AND($E53<=$F53,$E53<=$G53),"H",IF(AND($F53<=$E53,$F53<=$G53),"D","A"))) -> H | Q53: =IF($E53="","",0.5*((($P53="H")*1-($D53="H")*1)^2+((($P53="H")*1+($P53="D")*1)-(($D53="H")*1+($D53="D")*1))^2)) -> 1 | R53: =IF($E53="","",IF($P53=$D53,IF($P53="H",$E53,IF($P53="D",$F53,$G53))-1,-1)) -> -1 | S53: =IF($E53="","",0.5*((1/3-($D53="H")*1)^2+((2/3)-(($D53="H")*1+($D53="D")*1))^2)) -> 0.27777778 | U53: =IF(OR($T53="",$E53=""),"",$T53/IF($P53="H",$E53,IF($P53="D",$F53,$G53))-1)
A54: 46193 | B54: Netherlands v Sweden | C54: 5-1 | D54: =IF($C54="","",IF(VALUE(LEFT($C54,FIND("-",$C54)-1))>VALUE(MID($C54,FIND("-",$C54)+1,5)),"H",IF(VALUE(LEFT($C54,FIND("-",$C54)-1))=VALUE(MID($C54,FIND("-",$C54)+1,5)),"D","A"))) -> H | I54: =IF($E54="","",1/$E54+1/$F54+1/$G54) | J54: =IF($E54="","",(1/$E54)/$I54) | K54: =IF($E54="","",(1/$F54)/$I54) | L54: =IF($E54="","",(1/$G54)/$I54) | M54: =IF($E54="","",0.5*(($J54-($D54="H")*1)^2+(($J54+$K54)-(($D54="H")*1+($D54="D")*1))^2)) | N54: =IF($E54="","",($J54-($D54="H")*1)^2+($K54-($D54="D")*1)^2+($L54-($D54="A")*1)^2) | O54: =IF($E54="","",-LN(IF($D54="H",$J54,IF($D54="D",$K54,$L54)))) | P54: =IF($E54="","",IF(AND($E54<=$F54,$E54<=$G54),"H",IF(AND($F54<=$E54,$F54<=$G54),"D","A"))) | Q54: =IF($E54="","",0.5*((($P54="H")*1-($D54="H")*1)^2+((($P54="H")*1+($P54="D")*1)-(($D54="H")*1+($D54="D")*1))^2)) | R54: =IF($E54="","",IF($P54=$D54,IF($P54="H",$E54,IF($P54="D",$F54,$G54))-1,-1)) | S54: =IF($E54="","",0.5*((1/3-($D54="H")*1)^2+((2/3)-(($D54="H")*1+($D54="D")*1))^2)) | U54: =IF(OR($T54="",$E54=""),"",$T54/IF($P54="H",$E54,IF($P54="D",$F54,$G54))-1)
A55: 46193 | B55: Germany v Ivory Coast | C55: 2-1 | D55: =IF($C55="","",IF(VALUE(LEFT($C55,FIND("-",$C55)-1))>VALUE(MID($C55,FIND("-",$C55)+1,5)),"H",IF(VALUE(LEFT($C55,FIND("-",$C55)-1))=VALUE(MID($C55,FIND("-",$C55)+1,5)),"D","A"))) -> H | I55: =IF($E55="","",1/$E55+1/$F55+1/$G55) | J55: =IF($E55="","",(1/$E55)/$I55) | K55: =IF($E55="","",(1/$F55)/$I55) | L55: =IF($E55="","",(1/$G55)/$I55) | M55: =IF($E55="","",0.5*(($J55-($D55="H")*1)^2+(($J55+$K55)-(($D55="H")*1+($D55="D")*1))^2)) | N55: =IF($E55="","",($J55-($D55="H")*1)^2+($K55-($D55="D")*1)^2+($L55-($D55="A")*1)^2) | O55: =IF($E55="","",-LN(IF($D55="H",$J55,IF($D55="D",$K55,$L55)))) | P55: =IF($E55="","",IF(AND($E55<=$F55,$E55<=$G55),"H",IF(AND($F55<=$E55,$F55<=$G55),"D","A"))) | Q55: =IF($E55="","",0.5*((($P55="H")*1-($D55="H")*1)^2+((($P55="H")*1+($P55="D")*1)-(($D55="H")*1+($D55="D")*1))^2)) | R55: =IF($E55="","",IF($P55=$D55,IF($P55="H",$E55,IF($P55="D",$F55,$G55))-1,-1)) | S55: =IF($E55="","",0.5*((1/3-($D55="H")*1)^2+((2/3)-(($D55="H")*1+($D55="D")*1))^2)) | U55: =IF(OR($T55="",$E55=""),"",$T55/IF($P55="H",$E55,IF($P55="D",$F55,$G55))-1)
A56: 46193 | B56: Ecuador v Curacao | C56: 0-0 | D56: =IF($C56="","",IF(VALUE(LEFT($C56,FIND("-",$C56)-1))>VALUE(MID($C56,FIND("-",$C56)+1,5)),"H",IF(VALUE(LEFT($C56,FIND("-",$C56)-1))=VALUE(MID($C56,FIND("-",$C56)+1,5)),"D","A"))) -> D | I56: =IF($E56="","",1/$E56+1/$F56+1/$G56) | J56: =IF($E56="","",(1/$E56)/$I56) | K56: =IF($E56="","",(1/$F56)/$I56) | L56: =IF($E56="","",(1/$G56)/$I56) | M56: =IF($E56="","",0.5*(($J56-($D56="H")*1)^2+(($J56+$K56)-(($D56="H")*1+($D56="D")*1))^2)) | N56: =IF($E56="","",($J56-($D56="H")*1)^2+($K56-($D56="D")*1)^2+($L56-($D56="A")*1)^2) | O56: =IF($E56="","",-LN(IF($D56="H",$J56,IF($D56="D",$K56,$L56)))) | P56: =IF($E56="","",IF(AND($E56<=$F56,$E56<=$G56),"H",IF(AND($F56<=$E56,$F56<=$G56),"D","A"))) | Q56: =IF($E56="","",0.5*((($P56="H")*1-($D56="H")*1)^2+((($P56="H")*1+($P56="D")*1)-(($D56="H")*1+($D56="D")*1))^2)) | R56: =IF($E56="","",IF($P56=$D56,IF($P56="H",$E56,IF($P56="D",$F56,$G56))-1,-1)) | S56: =IF($E56="","",0.5*((1/3-($D56="H")*1)^2+((2/3)-(($D56="H")*1+($D56="D")*1))^2)) | U56: =IF(OR($T56="",$E56=""),"",$T56/IF($P56="H",$E56,IF($P56="D",$F56,$G56))-1)
A57: 46194 | B57: Tunisia v Japan | C57: 0-4 | D57: =IF($C57="","",IF(VALUE(LEFT($C57,FIND("-",$C57)-1))>VALUE(MID($C57,FIND("-",$C57)+1,5)),"H",IF(VALUE(LEFT($C57,FIND("-",$C57)-1))=VALUE(MID($C57,FIND("-",$C57)+1,5)),"D","A"))) -> A | I57: =IF($E57="","",1/$E57+1/$F57+1/$G57) | J57: =IF($E57="","",(1/$E57)/$I57) | K57: =IF($E57="","",(1/$F57)/$I57) | L57: =IF($E57="","",(1/$G57)/$I57) | M57: =IF($E57="","",0.5*(($J57-($D57="H")*1)^2+(($J57+$K57)-(($D57="H")*1+($D57="D")*1))^2)) | N57: =IF($E57="","",($J57-($D57="H")*1)^2+($K57-($D57="D")*1)^2+($L57-($D57="A")*1)^2) | O57: =IF($E57="","",-LN(IF($D57="H",$J57,IF($D57="D",$K57,$L57)))) | P57: =IF($E57="","",IF(AND($E57<=$F57,$E57<=$G57),"H",IF(AND($F57<=$E57,$F57<=$G57),"D","A"))) | Q57: =IF($E57="","",0.5*((($P57="H")*1-($D57="H")*1)^2+((($P57="H")*1+($P57="D")*1)-(($D57="H")*1+($D57="D")*1))^2)) | R57: =IF($E57="","",IF($P57=$D57,IF($P57="H",$E57,IF($P57="D",$F57,$G57))-1,-1)) | S57: =IF($E57="","",0.5*((1/3-($D57="H")*1)^2+((2/3)-(($D57="H")*1+($D57="D")*1))^2)) | U57: =IF(OR($T57="",$E57=""),"",$T57/IF($P57="H",$E57,IF($P57="D",$F57,$G57))-1)
A58: 46194 | B58: Spain v Saudi Arabia | C58: 4-0 | D58: =IF($C58="","",IF(VALUE(LEFT($C58,FIND("-",$C58)-1))>VALUE(MID($C58,FIND("-",$C58)+1,5)),"H",IF(VALUE(LEFT($C58,FIND("-",$C58)-1))=VALUE(MID($C58,FIND("-",$C58)+1,5)),"D","A"))) -> H | I58: =IF($E58="","",1/$E58+1/$F58+1/$G58) | J58: =IF($E58="","",(1/$E58)/$I58) | K58: =IF($E58="","",(1/$F58)/$I58) | L58: =IF($E58="","",(1/$G58)/$I58) | M58: =IF($E58="","",0.5*(($J58-($D58="H")*1)^2+(($J58+$K58)-(($D58="H")*1+($D58="D")*1))^2)) | N58: =IF($E58="","",($J58-($D58="H")*1)^2+($K58-($D58="D")*1)^2+($L58-($D58="A")*1)^2) | O58: =IF($E58="","",-LN(IF($D58="H",$J58,IF($D58="D",$K58,$L58)))) | P58: =IF($E58="","",IF(AND($E58<=$F58,$E58<=$G58),"H",IF(AND($F58<=$E58,$F58<=$G58),"D","A"))) | Q58: =IF($E58="","",0.5*((($P58="H")*1-($D58="H")*1)^2+((($P58="H")*1+($P58="D")*1)-(($D58="H")*1+($D58="D")*1))^2)) | R58: =IF($E58="","",IF($P58=$D58,IF($P58="H",$E58,IF($P58="D",$F58,$G58))-1,-1)) | S58: =IF($E58="","",0.5*((1/3-($D58="H")*1)^2+((2/3)-(($D58="H")*1+($D58="D")*1))^2)) | U58: =IF(OR($T58="",$E58=""),"",$T58/IF($P58="H",$E58,IF($P58="D",$F58,$G58))-1)
A59: 46194 | B59: Belgium v Iran | C59: 0-0 | D59: =IF($C59="","",IF(VALUE(LEFT($C59,FIND("-",$C59)-1))>VALUE(MID($C59,FIND("-",$C59)+1,5)),"H",IF(VALUE(LEFT($C59,FIND("-",$C59)-1))=VALUE(MID($C59,FIND("-",$C59)+1,5)),"D","A"))) -> D | I59: =IF($E59="","",1/$E59+1/$F59+1/$G59) | J59: =IF($E59="","",(1/$E59)/$I59) | K59: =IF($E59="","",(1/$F59)/$I59) | L59: =IF($E59="","",(1/$G59)/$I59) | M59: =IF($E59="","",0.5*(($J59-($D59="H")*1)^2+(($J59+$K59)-(($D59="H")*1+($D59="D")*1))^2)) | N59: =IF($E59="","",($J59-($D59="H")*1)^2+($K59-($D59="D")*1)^2+($L59-($D59="A")*1)^2) | O59: =IF($E59="","",-LN(IF($D59="H",$J59,IF($D59="D",$K59,$L59)))) | P59: =IF($E59="","",IF(AND($E59<=$F59,$E59<=$G59),"H",IF(AND($F59<=$E59,$F59<=$G59),"D","A"))) | Q59: =IF($E59="","",0.5*((($P59="H")*1-($D59="H")*1)^2+((($P59="H")*1+($P59="D")*1)-(($D59="H")*1+($D59="D")*1))^2)) | R59: =IF($E59="","",IF($P59=$D59,IF($P59="H",$E59,IF($P59="D",$F59,$G59))-1,-1)) | S59: =IF($E59="","",0.5*((1/3-($D59="H")*1)^2+((2/3)-(($D59="H")*1+($D59="D")*1))^2)) | U59: =IF(OR($T59="",$E59=""),"",$T59/IF($P59="H",$E59,IF($P59="D",$F59,$G59))-1)
A60: 46194 | B60: Uruguay v Cape Verde | C60: 1-1 | D60: =IF($C60="","",IF(VALUE(LEFT($C60,FIND("-",$C60)-1))>VALUE(MID($C60,FIND("-",$C60)+1,5)),"H",IF(VALUE(LEFT($C60,FIND("-",$C60)-1))=VALUE(MID($C60,FIND("-",$C60)+1,5)),"D","A"))) -> D | I60: =IF($E60="","",1/$E60+1/$F60+1/$G60) | J60: =IF($E60="","",(1/$E60)/$I60) | K60: =IF($E60="","",(1/$F60)/$I60) | L60: =IF($E60="","",(1/$G60)/$I60) | M60: =IF($E60="","",0.5*(($J60-($D60="H")*1)^2+(($J60+$K60)-(($D60="H")*1+($D60="D")*1))^2)) | N60: =IF($E60="","",($J60-($D60="H")*1)^2+($K60-($D60="D")*1)^2+($L60-($D60="A")*1)^2) | O60: =IF($E60="","",-LN(IF($D60="H",$J60,IF($D60="D",$K60,$L60)))) | P60: =IF($E60="","",IF(AND($E60<=$F60,$E60<=$G60),"H",IF(AND($F60<=$E60,$F60<=$G60),"D","A"))) | Q60: =IF($E60="","",0.5*((($P60="H")*1-($D60="H")*1)^2+((($P60="H")*1+($P60="D")*1)-(($D60="H")*1+($D60="D")*1))^2)) | R60: =IF($E60="","",IF($P60=$D60,IF($P60="H",$E60,IF($P60="D",$F60,$G60))-1,-1)) | S60: =IF($E60="","",0.5*((1/3-($D60="H")*1)^2+((2/3)-(($D60="H")*1+($D60="D")*1))^2)) | U60: =IF(OR($T60="",$E60=""),"",$T60/IF($P60="H",$E60,IF($P60="D",$F60,$G60))-1)
A61: 46194 | B61: New Zealand v Egypt | C61: 1-3 | D61: =IF($C61="","",IF(VALUE(LEFT($C61,FIND("-",$C61)-1))>VALUE(MID($C61,FIND("-",$C61)+1,5)),"H",IF(VALUE(LEFT($C61,FIND("-",$C61)-1))=VALUE(MID($C61,FIND("-",$C61)+1,5)),"D","A"))) -> A | I61: =IF($E61="","",1/$E61+1/$F61+1/$G61) | J61: =IF($E61="","",(1/$E61)/$I61) | K61: =IF($E61="","",(1/$F61)/$I61) | L61: =IF($E61="","",(1/$G61)/$I61) | M61: =IF($E61="","",0.5*(($J61-($D61="H")*1)^2+(($J61+$K61)-(($D61="H")*1+($D61="D")*1))^2)) | N61: =IF($E61="","",($J61-($D61="H")*1)^2+($K61-($D61="D")*1)^2+($L61-($D61="A")*1)^2) | O61: =IF($E61="","",-LN(IF($D61="H",$J61,IF($D61="D",$K61,$L61)))) | P61: =IF($E61="","",IF(AND($E61<=$F61,$E61<=$G61),"H",IF(AND($F61<=$E61,$F61<=$G61),"D","A"))) | Q61: =IF($E61="","",0.5*((($P61="H")*1-($D61="H")*1)^2+((($P61="H")*1+($P61="D")*1)-(($D61="H")*1+($D61="D")*1))^2)) | R61: =IF($E61="","",IF($P61=$D61,IF($P61="H",$E61,IF($P61="D",$F61,$G61))-1,-1)) | S61: =IF($E61="","",0.5*((1/3-($D61="H")*1)^2+((2/3)-(($D61="H")*1+($D61="D")*1))^2)) | U61: =IF(OR($T61="",$E61=""),"",$T61/IF($P61="H",$E61,IF($P61="D",$F61,$G61))-1)
A62: 46195 | B62: Argentina v Austria | C62: 2-0 | D62: =IF($C62="","",IF(VALUE(LEFT($C62,FIND("-",$C62)-1))>VALUE(MID($C62,FIND("-",$C62)+1,5)),"H",IF(VALUE(LEFT($C62,FIND("-",$C62)-1))=VALUE(MID($C62,FIND("-",$C62)+1,5)),"D","A"))) -> H | I62: =IF($E62="","",1/$E62+1/$F62+1/$G62) | J62: =IF($E62="","",(1/$E62)/$I62) | K62: =IF($E62="","",(1/$F62)/$I62) | L62: =IF($E62="","",(1/$G62)/$I62) | M62: =IF($E62="","",0.5*(($J62-($D62="H")*1)^2+(($J62+$K62)-(($D62="H")*1+($D62="D")*1))^2)) | N62: =IF($E62="","",($J62-($D62="H")*1)^2+($K62-($D62="D")*1)^2+($L62-($D62="A")*1)^2) | O62: =IF($E62="","",-LN(IF($D62="H",$J62,IF($D62="D",$K62,$L62)))) | P62: =IF($E62="","",IF(AND($E62<=$F62,$E62<=$G62),"H",IF(AND($F62<=$E62,$F62<=$G62),"D","A"))) | Q62: =IF($E62="","",0.5*((($P62="H")*1-($D62="H")*1)^2+((($P62="H")*1+($P62="D")*1)-(($D62="H")*1+($D62="D")*1))^2)) | R62: =IF($E62="","",IF($P62=$D62,IF($P62="H",$E62,IF($P62="D",$F62,$G62))-1,-1)) | S62: =IF($E62="","",0.5*((1/3-($D62="H")*1)^2+((2/3)-(($D62="H")*1+($D62="D")*1))^2)) | U62: =IF(OR($T62="",$E62=""),"",$T62/IF($P62="H",$E62,IF($P62="D",$F62,$G62))-1)
A63: 46195 | B63: France v Iraq | C63: 3-0 | D63: =IF($C63="","",IF(VALUE(LEFT($C63,FIND("-",$C63)-1))>VALUE(MID($C63,FIND("-",$C63)+1,5)),"H",IF(VALUE(LEFT($C63,FIND("-",$C63)-1))=VALUE(MID($C63,FIND("-",$C63)+1,5)),"D","A"))) -> H | I63: =IF($E63="","",1/$E63+1/$F63+1/$G63) | J63: =IF($E63="","",(1/$E63)/$I63) | K63: =IF($E63="","",(1/$F63)/$I63) | L63: =IF($E63="","",(1/$G63)/$I63) | M63: =IF($E63="","",0.5*(($J63-($D63="H")*1)^2+(($J63+$K63)-(($D63="H")*1+($D63="D")*1))^2)) | N63: =IF($E63="","",($J63-($D63="H")*1)^2+($K63-($D63="D")*1)^2+($L63-($D63="A")*1)^2) | O63: =IF($E63="","",-LN(IF($D63="H",$J63,IF($D63="D",$K63,$L63)))) | P63: =IF($E63="","",IF(AND($E63<=$F63,$E63<=$G63),"H",IF(AND($F63<=$E63,$F63<=$G63),"D","A"))) | Q63: =IF($E63="","",0.5*((($P63="H")*1-($D63="H")*1)^2+((($P63="H")*1+($P63="D")*1)-(($D63="H")*1+($D63="D")*1))^2)) | R63: =IF($E63="","",IF($P63=$D63,IF($P63="H",$E63,IF($P63="D",$F63,$G63))-1,-1)) | S63: =IF($E63="","",0.5*((1/3-($D63="H")*1)^2+((2/3)-(($D63="H")*1+($D63="D")*1))^2)) | U63: =IF(OR($T63="",$E63=""),"",$T63/IF($P63="H",$E63,IF($P63="D",$F63,$G63))-1)
A64: 46195 | B64: Norway v Senegal | C64: 3-2 | D64: =IF($C64="","",IF(VALUE(LEFT($C64,FIND("-",$C64)-1))>VALUE(MID($C64,FIND("-",$C64)+1,5)),"H",IF(VALUE(LEFT($C64,FIND("-",$C64)-1))=VALUE(MID($C64,FIND("-",$C64)+1,5)),"D","A"))) -> H | E64: 2.22 | F64: 3.57 | G64: 3.45 | H64: Kalshi (close) | I64: =IF($E64="","",1/$E64+1/$F64+1/$G64) -> 1.0204176 | J64: =IF($E64="","",(1/$E64)/$I64) -> 0.44143737 | K64: =IF($E64="","",(1/$F64)/$I64) -> 0.27450727 | L64: =IF($E64="","",(1/$G64)/$I64) -> 0.28405535 | M64: =IF($E64="","",0.5*(($J64-($D64="H")*1)^2+(($J64+$K64)-(($D64="H")*1+($D64="D")*1))^2)) -> 0.19633983 | N64: =IF($E64="","",($J64-($D64="H")*1)^2+($K64-($D64="D")*1)^2+($L64-($D64="A")*1)^2) -> 0.4680339 | O64: =IF($E64="","",-LN(IF($D64="H",$J64,IF($D64="D",$K64,$L64)))) -> 0.81771912 | P64: =IF($E64="","",IF(AND($E64<=$F64,$E64<=$G64),"H",IF(AND($F64<=$E64,$F64<=$G64),"D","A"))) -> H | Q64: =IF($E64="","",0.5*((($P64="H")*1-($D64="H")*1)^2+((($P64="H")*1+($P64="D")*1)-(($D64="H")*1+($D64="D")*1))^2)) -> 0 | R64: =IF($E64="","",IF($P64=$D64,IF($P64="H",$E64,IF($P64="D",$F64,$G64))-1,-1)) -> 1.22 | S64: =IF($E64="","",0.5*((1/3-($D64="H")*1)^2+((2/3)-(($D64="H")*1+($D64="D")*1))^2)) -> 0.27777778 | U64: =IF(OR($T64="",$E64=""),"",$T64/IF($P64="H",$E64,IF($P64="D",$F64,$G64))-1)
A65: 46195 | B65: Jordan v Algeria | C65: 1-2 | D65: =IF($C65="","",IF(VALUE(LEFT($C65,FIND("-",$C65)-1))>VALUE(MID($C65,FIND("-",$C65)+1,5)),"H",IF(VALUE(LEFT($C65,FIND("-",$C65)-1))=VALUE(MID($C65,FIND("-",$C65)+1,5)),"D","A"))) -> A | I65: =IF($E65="","",1/$E65+1/$F65+1/$G65) | J65: =IF($E65="","",(1/$E65)/$I65) | K65: =IF($E65="","",(1/$F65)/$I65) | L65: =IF($E65="","",(1/$G65)/$I65) | M65: =IF($E65="","",0.5*(($J65-($D65="H")*1)^2+(($J65+$K65)-(($D65="H")*1+($D65="D")*1))^2)) | N65: =IF($E65="","",($J65-($D65="H")*1)^2+($K65-($D65="D")*1)^2+($L65-($D65="A")*1)^2) | O65: =IF($E65="","",-LN(IF($D65="H",$J65,IF($D65="D",$K65,$L65)))) | P65: =IF($E65="","",IF(AND($E65<=$F65,$E65<=$G65),"H",IF(AND($F65<=$E65,$F65<=$G65),"D","A"))) | Q65: =IF($E65="","",0.5*((($P65="H")*1-($D65="H")*1)^2+((($P65="H")*1+($P65="D")*1)-(($D65="H")*1+($D65="D")*1))^2)) | R65: =IF($E65="","",IF($P65=$D65,IF($P65="H",$E65,IF($P65="D",$F65,$G65))-1,-1)) | S65: =IF($E65="","",0.5*((1/3-($D65="H")*1)^2+((2/3)-(($D65="H")*1+($D65="D")*1))^2)) | U65: =IF(OR($T65="",$E65=""),"",$T65/IF($P65="H",$E65,IF($P65="D",$F65,$G65))-1)
...
